<?xml version="1.0"?>
<robot name="AutoObjectTransport">

  <material name="gray">
      <color rgba="0.66 0.66 0.66 1"/>
  </material>


  <link name="base_link">
    <inertial>
      <mass value="0.0001"/>
      <origin xyz="0.0 0.0 0.0"/>
      <inertia ixx="1e-10" ixy="0." ixz="0." iyy="1e-10" iyz="0." izz="1e-10"/>
    </inertial>
  </link>

  <link name="apex_link_x">
    <inertial>
      <mass value="0.0001"/>
      <origin xyz="0.0 0.0 0.0"/>
      <inertia ixx="1e-10" ixy="0." ixz="0." iyy="1e-10" iyz="0." izz="1e-10"/>
    </inertial>
  </link>

  <link name="apex_link_y">
    <inertial>
      <mass value="0.0001"/>
      <origin xyz="0.0 0.0 0.0"/>
      <inertia ixx="1e-10" ixy="0." ixz="0." iyy="1e-10" iyz="0." izz="1e-10"/>
    </inertial>
  </link>

  <link name="apex_link_z">
    <inertial>
      <mass value="0.0001"/>
      <origin xyz="0.0 0.0 0.0"/>
      <inertia ixx="1e-10" ixy="0." ixz="0." iyy="1e-10" iyz="0." izz="1e-10"/>
    </inertial>
  </link>

  <link name="apex_link_dummy_1">
    <inertial>
      <mass value="0.0001"/>
      <origin xyz="0.0 0.0 0.0"/>
      <inertia ixx="1e-10" ixy="0." ixz="0." iyy="1e-10" iyz="0." izz="1e-10"/>
    </inertial>
  </link>

  <link name="apex_link_dummy_2">
    <inertial>
      <mass value="0.0001"/>
      <origin xyz="0.0 0.0 0.0"/>
      <inertia ixx="1e-10" ixy="0." ixz="0." iyy="1e-10" iyz="0." izz="1e-10"/>
    </inertial>
  </link>

  <link name="cone">
    <inertial>
      <mass value="1.8728423076371943"/>
      <origin xyz="1.273596164365472e-17 0.26179734388357667 -1.0977046482824309"/>
      <inertia ixx="0.19333087716102926" ixy="-7.666665709704074e-19" ixz="-3.4278319038360554e-17" iyy="0.18477350490922834" iyz="0.03588068220456063" izz="0.07721216479087363"/>
    </inertial>

    <contact>
      <lateral_friction value="0.4"/>
    </contact>

    <visual>
      <origin rpy="0 0 0" xyz="0 0 0"/>
      <geometry>
        <mesh filename="mesh/object_mesh.obj"/>
      </geometry>
      <material name="gray"/>
    </visual>

    <collision>
      <origin rpy="0 0 0" xyz="0 0 0"/>
      <geometry>
        <mesh filename="mesh/object_mesh.obj"/>
      </geometry>
    </collision>

  </link>


  <joint name="joint_apex_x" type="prismatic">
    <axis xyz="1 0 0"/>
    <parent link="base_link"/>
    <child link="apex_link_x"/>
    <limit lower="-100" upper="100"/>
  </joint>

  <joint name="joint_apex_y" type="prismatic">
    <axis xyz="0 1 0"/>
    <parent link="apex_link_x"/>
    <child link="apex_link_y"/>
    <limit lower="-100" upper="100"/>
  </joint>

  <joint name="joint_apex_z" type="prismatic">
    <axis xyz="0 0 1"/>
    <parent link="apex_link_y"/>
    <child link="apex_link_z"/>
    <limit lower="-100" upper="100"/>
  </joint>

  <joint name="joint_apex_dummy_1" type="spherical">
    <axis xyz="0 0 1"/>
    <parent link="apex_link_z"/>
    <child link="apex_link_dummy_1"/>
  </joint>

  <joint name="joint_apex_dummy_2" type="spherical">
    <axis xyz="0 1 0"/>
    <parent link="apex_link_dummy_1"/>
    <child link="apex_link_dummy_2"/>
  </joint>

  <joint name="joint_apex_dummy_3" type="spherical">
    <axis xyz="1 0 0"/>
    <parent link="apex_link_dummy_2"/>
    <child link="cone"/>
  </joint>

</robot>