<?xml version="1.0"?>
<robot name="LargeConeControl">


  <link name="base_link">
    <inertial>
      <mass value="0.0001"/>
      <origin xyz="0.0 0.0 0.0"/>
      <inertia ixx="1e-10" ixy="0." ixz="0." iyy="1e-10" iyz="0." izz="1e-10"/>
    </inertial>
  </link>

  <link name="apex_link_x">
    <inertial>
      <mass value="0.0001"/>
      <origin xyz="0.0 0.0 0.0"/>
      <inertia ixx="1e-10" ixy="0." ixz="0." iyy="1e-10" iyz="0." izz="1e-10"/>
    </inertial>
  </link>

  <link name="apex_link_y">
    <inertial>
      <mass value="0.0001"/>
      <origin xyz="0.0 0.0 0.0"/>
      <inertia ixx="1e-10" ixy="0." ixz="0." iyy="1e-10" iyz="0." izz="1e-10"/>
    </inertial>
  </link>

  <link name="apex_link_z">
    <inertial>
      <mass value="0.0001"/>
      <origin xyz="0.0 0.0 0.0"/>
      <inertia ixx="1e-10" ixy="0." ixz="0." iyy="1e-10" iyz="0." izz="1e-10"/>
    </inertial>
  </link>

  <link name="apex_link_dummy">
    <inertial>
      <mass value="0.0001"/>
      <origin xyz="0.0 0.0 0.0"/>
      <inertia ixx="1e-10" ixy="0." ixz="0." iyy="1e-10" iyz="0." izz="1e-10"/>
    </inertial>
  </link>

  <joint name="joint_apex_x" type="prismatic">
    <axis xyz="1 0 0"/>
    <parent link="base_link"/>
    <child link="apex_link_x"/>
    <limit lower="-100" upper="100"/>
  </joint>

  <joint name="joint_apex_y" type="prismatic">
    <axis xyz="0 1 0"/>
    <parent link="apex_link_x"/>
    <child link="apex_link_y"/>
    <limit lower="-100" upper="100"/>
  </joint>

  <joint name="joint_apex_z" type="prismatic">
    <axis xyz="0 0 1"/>
    <parent link="apex_link_y"/>
    <child link="apex_link_z"/>
    <limit lower="-100" upper="100"/>
  </joint>

  <joint name="joint_apex_dummy" type="planar">
    <axis xyz="0 1 0"/>
    <parent link="apex_link_z"/>
    <child link="apex_link_dummy"/>
    <limit lower="-100" upper="100"/>
  </joint>

</robot>
